Workbook
Name Slicer_ai_model_name: #N/A
Name Slicer_education_level: #N/A
Name Slicer_performed_fact_check: #N/A

Sheet OG Data
A1: ai_model_name | B1: query_category | C1: ai_confidence_percentage | D1: response_character_count | E1: has_cited_sources | F1: contains_hedging_words | G1: includes_disclaimer | H1: answer_detail_level | I1: respondent_age_bracket | J1: education_level | K1: digital_literacy_score | L1: ai_familiarity_level | M1: decision_importance | N1: urgency_level | O1: belief_alignment_status | P1: subject_matter_expertise | Q1: trust_score_out_of_10 | R1: performed_fact_check | S1: fact_check_method_used | T1: verification_duration_mins | U1: answer_accuracy_percentage | V1: trust_calibration_valid | W1: user_skepticism_category
A2: Claude | B2: math_calculation | C2: 93.23 | D2: 527 | E2: TRUE | F2: FALSE | G2: FALSE | H2: Moderate | I2: 45-54 | J2: Bachelors | K2: Low | L2: Intermediate | M2: Low | N2: Low | O2: FALSE | P2: FALSE | Q2: 10 | R2: TRUE | S2: Google Search | T2: 10.7 | U2: 80.15 | V2: TRUE | W2: Moderate Trust
A3: Llama | B3: recipe_cooking | C3: 84.47 | D3: 581 | E3: FALSE | F3: FALSE | G3: FALSE | H3: Specific | I3: 55-64 | J3: PhD | K3: Expert | L3: First Time | M3: High | O3: FALSE | P3: TRUE | Q3: 7.9 | R3: TRUE | S3: Asked Expert | T3: 44.3 | U3: 92.33 | V3: TRUE | W3: Skeptical
A4: Claude | B4: general_knowledge | C4: 69.82 | D4: 484 | E4: TRUE | F4: TRUE | G4: FALSE | H4: Very Specific | I4: 35-44 | J4: High School | K4: Medium | L4: Intermediate | M4: Critical | O4: TRUE | P4: FALSE | Q4: 8.6 | R4: TRUE | S4: Consulted Documentation | T4: 37.5 | U4: 67.32 | V4: TRUE | W4: Moderate Trust
A5: Claude | B5: creative_writing | C5: 79.61 | D5: 73 | E5: TRUE | F5: TRUE | G5: FALSE | H5: Specific | I5: 45-54 | J5: Professional | K5: Low | L5: Advanced | M5: High | P5: FALSE | Q5: 8.9 | R5: TRUE | S5: Checked Official Source | T5: 22.7 | U5: 73.12 | V5: TRUE | W5: Moderate Trust
A6: Claude | B6: creative_writing | C6: 67.71 | D6: 146 | E6: FALSE | F6: TRUE | G6: FALSE | H6: Vague | I6: 55-64 | J6: Masters | K6: Low | L6: Expert | M6: Low | O6: TRUE | P6: TRUE | Q6: 9 | R6: TRUE | S6: Academic Paper | T6: 43.7 | U6: 81.05 | V6: TRUE | W6: Moderate Trust
A7: Mistral | B7: math_calculation | C7: 93.41 | D7: 198 | E7: FALSE | F7: TRUE | G7: FALSE | H7: Moderate | I7: 18-24 | J7: Professional | K7: Expert | L7: Advanced | M7: Medium | O7: FALSE | P7: FALSE | Q7: 8.2 | R7: FALSE | T7: 0 | U7: 100 | V7: TRUE | W7: Blind Trust
A8: Claude | B8: technical_coding | C8: 75.87 | D8: 285 | E8: FALSE | F8: FALSE | G8: TRUE | H8: Very Specific | I8: 18-24 | J8: High School | K8: Expert | L8: Expert | M8: Low | N8: High | O8: FALSE | P8: TRUE | Q8: 7.6 | R8: FALSE | T8: 0 | U8: 79.04 | V8: TRUE | W8: Moderate Trust
A9: Claude | B9: financial_advice | C9: 57.32 | D9: 371 | E9: TRUE | F9: FALSE | G9: FALSE | H9: Vague | I9: 55-64 | J9: Professional | K9: Medium | L9: First Time | M9: Critical | N9: High | P9: FALSE | Q9: 6.4 | R9: FALSE | T9: 0 | U9: 55.65 | V9: TRUE | W9: Moderate Trust
A10: ChatGPT-3.5 | B10: medical_advice | C10: 50.17 | D10: 344 | E10: FALSE | F10: FALSE | G10: TRUE | H10: Vague | I10: 65+ | J10: PhD | K10: Medium | L10: Advanced | M10: Medium | N10: High | P10: FALSE | Q10: 5.3 | R10: TRUE | S10: Personal Testing | T10: 20 | U10: 41.69 | V10: TRUE | W10: Skeptical
A11: Llama | B11: medical_advice | C11: 58.77 | D11: 63 | E11: FALSE | F11: FALSE | G11: TRUE | H11: Vague | I11: 65+ | J11: Professional | K11: Low | L11: Expert | M11: Medium | N11: Low | O11: FALSE | P11: FALSE | Q11: 5.6 | R11: TRUE | S11: Cross-referenced Multiple AIs | T11: 23.5 | U11: 50.81 | V11: TRUE | W11: Skeptical
A12: Claude | B12: general_knowledge | C12: 82.85 | D12: 331 | E12: TRUE | F12: TRUE | G12: TRUE | H12: Specific | I12: 45-54 | J12: Masters | K12: Expert | L12: First Time | M12: Medium | N12: Medium | P12: TRUE | Q12: 10 | R12: TRUE | S12: Academic Paper | T12: 22.9 | U12: 68.05 | V12: FALSE | W12: Moderate Trust
A13: Claude | B13: recipe_cooking | C13: 76.69 | D13: 70 | E13: TRUE | F13: FALSE | G13: TRUE | H13: Moderate | I13: 18-24 | J13: Professional | K13: Low | L13: Expert | M13: Low | N13: Medium | P13: TRUE | Q13: 9.9 | R13: FALSE | T13: 0 | U13: 62.11 | V13: FALSE | W13: Blind Trust
A14: Llama | B14: current_events | C14: 77.43 | D14: 549 | E14: FALSE | F14: FALSE | G14: TRUE | H14: Vague | I14: 25-34 | J14: PhD | K14: High | L14: Advanced | M14: Low | N14: Medium | O14: TRUE | P14: FALSE | Q14: 9.5 | R14: TRUE | S14: Checked Official Source | T14: 33.8 | U14: 73.81 | V14: FALSE | W14: Moderate Trust
A15: Gemini | B15: recipe_cooking | C15: 78.83 | D15: 419 | E15: FALSE | F15: TRUE | G15: FALSE | H15: Specific | I15: 35-44 | J15: High School | K15: Expert | L15: Advanced | M15: Medium | N15: Medium | P15: FALSE | Q15: 7.2 | R15: TRUE | S15: Cross-referenced Multiple AIs | T15: 41.9 | U15: 81.22 | V15: TRUE | W15: Skeptical
A16: Gemini | B16: creative_writing | C16: 75 | D16: 386 | E16: FALSE | F16: TRUE | G16: TRUE | H16: Moderate | I16: 45-54 | J16: Professional | K16: Medium | L16: Intermediate | M16: Low | N16: Medium | O16: TRUE | P16: FALSE | Q16: 9.9 | R16: FALSE | T16: 0 | U16: 66.21 | V16: FALSE | W16: Blind Trust
A17: Gemini | B17: current_events | C17: 55.73 | D17: 698 | E17: TRUE | F17: TRUE | G17: FALSE | H17: Moderate | I17: 18-24 | J17: Bachelors | K17: Low | L17: Beginner | M17: Critical | N17: High | O17: FALSE | P17: TRUE | Q17: 5.2 | R17: FALSE | T17: 0 | U17: 55.92 | V17: TRUE | W17: Skeptical
A18: Gemini | B18: factual_historical | C18: 79.42 | D18: 382 | E18: FALSE | F18: FALSE | G18: TRUE | H18: Vague | I18: 18-24 | J18: Professional | K18: Expert | L18: Advanced | M18: High | N18: High | O18: FALSE | P18: FALSE | Q18: 6.7 | R18: TRUE | S18: Asked Expert | T18: 30 | U18: 88.58 | V18: FALSE | W18: Skeptical
A19: Claude | B19: opinion_based | C19: 47.7 | D19: 53 | E19: FALSE | F19: TRUE | G19: FALSE | H19: Vague | I19: 65+ | J19: PhD | K19: High | L19: Beginner | M19: Critical | N19: Low | O19: FALSE | P19: TRUE | Q19: 2.9 | R19: TRUE | S19: Academic Paper | T19: 29.9 | U19: 40.41 | V19: TRUE | W19: Highly Skeptical
A20: ChatGPT-3.5 | B20: legal_advice | C20: 52.94 | D20: 725 | E20: TRUE | F20: FALSE | G20: TRUE | H20: Vague | I20: 55-64 | J20: PhD | K20: Medium | L20: Intermediate | M20: Critical | N20: Medium | O20: FALSE | P20: TRUE | Q20: 4.7 | R20: TRUE | S20: Personal Testing | T20: 36.1 | U20: 38.72 | V20: TRUE | W20: Highly Skeptical
A21: Gemini | B21: technical_coding | C21: 91.49 | D21: 457 | E21: TRUE | F21: TRUE | G21: FALSE | H21: Very Specific | I21: 35-44 | J21: Masters | K21: Expert | L21: Advanced | M21: Medium | N21: Low | P21: TRUE | Q21: 9.4 | R21: FALSE | T21: 0 | U21: 78.01 | V21: TRUE | W21: Blind Trust
A22: Llama | B22: recipe_cooking | C22: 85.85 | D22: 617 | E22: FALSE | F22: TRUE | G22: FALSE | H22: Specific | I22: 55-64 | J22: Bachelors | K22: Low | L22: Beginner | M22: Low | N22: Low | P22: FALSE | Q22: 9.9 | R22: TRUE | S22: Cross-referenced Multiple AIs | T22: 42.1 | U22: 77.63 | V22: FALSE | W22: Moderate Trust
A23: Claude | B23: financial_advice | C23: 55.95 | D23: 166 | E23: TRUE | F23: FALSE | G23: TRUE | H23: Very Specific | I23: 18-24 | J23: Masters | K23: Medium | L23: First Time | M23: High | N23: High | P23: TRUE | Q23: 7.7 | R23: TRUE | S23: Checked Official Source | T23: 34.3 | U23: 55.71 | V23: FALSE | W23: Skeptical
A24: Mistral | B24: current_events | C24: 75.51 | D24: 289 | E24: TRUE | F24: FALSE | G24: TRUE | H24: Specific | I24: 45-54 | J24: Masters | K24: Low | L24: First Time | M24: High | N24: Low | O24: TRUE | P24: TRUE | Q24: 10 | R24: TRUE | S24: Google Search | T24: 13 | U24: 53.58 | V24: FALSE | W24: Moderate Trust
A25: Llama | B25: opinion_based | C25: 42.81 | D25: 86 | E25: TRUE | F25: FALSE | G25: TRUE | H25: Very Specific | I25: 45-54 | J25: Masters | K25: Low | L25: Intermediate | M25: Critical | N25: High | O25: FALSE | P25: FALSE | Q25: 2.7 | R25: TRUE | S25: Academic Paper | T25: 2.5 | U25: 21.4 | V25: TRUE | W25: Highly Skeptical
A26: GPT-4 | B26: current_events | C26: 62.31 | D26: 51 | E26: FALSE | F26: TRUE | G26: TRUE | H26: Very Specific | I26: 65+ | J26: PhD | K26: Low | L26: Beginner | M26: High | N26: Low | O26: FALSE | P26: FALSE | Q26: 4.8 | R26: TRUE | S26: Cross-referenced Multiple AIs | T26: 26.2 | U26: 40.83 | V26: TRUE | W26: Highly Skeptical
A27: GPT-4 | B27: current_events | C27: 65.12 | D27: 320 | E27: FALSE | F27: TRUE | G27: TRUE | H27: Very Specific | I27: 18-24 | J27: PhD | K27: Expert | L27: Beginner | M27: High | O27: TRUE | P27: FALSE | Q27: 7.5 | R27: TRUE | S27: Personal Testing | T27: 11.5 | U27: 61.68 | V27: TRUE | W27: Skeptical
A28: Claude | B28: legal_advice | C28: 64.2 | D28: 293 | E28: TRUE | F28: FALSE | G28: FALSE | H28: Specific | I28: 65+ | J28: PhD | K28: High | L28: Expert | M28: Low | N28: High | O28: FALSE | P28: FALSE | Q28: 6.6 | R28: TRUE | S28: Google Search | T28: 27.5 | U28: 59.63 | V28: TRUE | W28: Skeptical
A29: Claude | B29: creative_writing | C29: 64.93 | D29: 177 | E29: TRUE | F29: FALSE | G29: FALSE | H29: Very Specific | I29: 65+ | J29: Masters | K29: Low | L29: Advanced | M29: Low | N29: Low | O29: TRUE | P29: FALSE | Q29: 9.4 | R29: TRUE | S29: Checked Official Source | T29: 30.4 | U29: 67.76 | V29: FALSE | W29: Moderate Trust
A30: Gemini | B30: technical_coding | C30: 75.1 | D30: 107 | E30: FALSE | F30: FALSE | G30: TRUE | H30: Moderate | I30: 65+ | J30: PhD | K30: Expert | L30: Beginner | M30: High | O30: TRUE | P30: TRUE | Q30: 9.5 | R30: TRUE | S30: Consulted Documentation | T30: 37.6 | U30: 69.68 | V30: FALSE | W30: Moderate Trust
A31: ChatGPT-3.5 | B31: opinion_based | C31: 43.22 | D31: 345 | E31: TRUE | F31: TRUE | G31: TRUE | H31: Moderate | I31: 35-44 | J31: High School | K31: Low | L31: Intermediate | M31: High | N31: Medium | O31: FALSE | P31: FALSE | Q31: 4.3 | R31: FALSE | T31: 0 | U31: 26.69 | V31: TRUE | W31: Skeptical
A32: Gemini | B32: legal_advice | C32: 58.29 | D32: 776 | E32: TRUE | F32: FALSE | G32: TRUE | H32: Vague | I32: 65+ | J32: PhD | K32: Low | L32: First Time | M32: Low | N32: High | O32: TRUE | P32: TRUE | Q32: 10 | R32: FALSE | T32: 0 | U32: 63.76 | V32: FALSE | W32: Blind Trust
A33: Llama | B33: current_events | C33: 76.42 | D33: 466 | E33: TRUE | F33: FALSE | G33: FALSE | H33: Moderate | I33: 35-44 | J33: Masters | K33: Expert | L33: Expert | M33: Critical | O33: TRUE | P33: TRUE | Q33: 9.4 | R33: TRUE | S33: Google Search | T33: 30.9 | U33: 66.39 | V33: FALSE | W33: Moderate Trust
A34: Gemini | B34: financial_advice | C34: 48.76 | D34: 60 | E34: FALSE | F34: TRUE | G34: TRUE | H34: Moderate | I34: 65+ | J34: Bachelors | K34: Medium | L34: Beginner | M34: Medium | N34: Low | O34: TRUE | P34: FALSE | Q34: 7.3 | R34: TRUE | S34: Checked Official Source | T34: 26.3 | U34: 47.61 | V34: FALSE | W34: Skeptical
A35: GPT-4 | B35: math_calculation | C35: 92.82 | D35: 541 | E35: TRUE | F35: FALSE | G35: FALSE | H35: Moderate | I35: 65+ | J35: High School | K35: Medium | L35: Beginner | M35: Medium | P35: FALSE | Q35: 10 | R35: FALSE | T35: 0 | U35: 90.77 | V35: TRUE | W35: Blind Trust
A36: Mistral | B36: financial_advice | C36: 46.95 | D36: 521 | E36: FALSE | F36: FALSE | G36: FALSE | H36: Vague | I36: 55-64 | J36: High School | K36: Expert | L36: Intermediate | M36: Low | P36: FALSE | Q36: 5.2 | R36: TRUE | S36: Academic Paper | T36: 25.5 | U36: 58.55 | V36: TRUE | W36: Skeptical
A37: Claude | B37: creative_writing | C37: 60.77 | D37: 442 | E37: TRUE | F37: TRUE | G37: TRUE | H37: Moderate | I37: 35-44 | J37: High School | K37: Expert | L37: Beginner | M37: Low | N37: Low | P37: FALSE | Q37: 8 | R37: TRUE | S37: Personal Testing | T37: 35 | U37: 71.84 | V37: TRUE | W37: Moderate Trust
A38: Claude | B38: financial_advice | C38: 56.58 | D38: 688 | E38: FALSE | F38: TRUE | G38: FALSE | H38: Moderate | I38: 35-44 | J38: High School | K38: Expert | L38: First Time | M38: Medium | P38: TRUE | Q38: 5.7 | R38: TRUE | S38: Google Search | T38: 14.8 | U38: 48.42 | V38: TRUE | W38: Skeptical
A39: Claude | B39: math_calculation | C39: 98.66 | D39: 109 | E39: FALSE | F39: TRUE | G39: TRUE | H39: Specific | I39: 45-54 | J39: Professional | K39: High | L39: Beginner | M39: Medium | O39: FALSE | P39: TRUE | Q39: 9.1 | R39: TRUE | S39: Cross-referenced Multiple AIs | T39: 16.6 | U39: 89.95 | V39: TRUE | W39: Moderate Trust
A40: Claude | B40: math_calculation | C40: 89.07 | D40: 258 | E40: FALSE | F40: FALSE | G40: TRUE | H40: Very Specific | I40: 55-64 | J40: Masters | K40: Expert | L40: Expert | M40: High | N40: Medium | O40: TRUE | P40: FALSE | Q40: 10 | R40: TRUE | S40: Asked Colleague | T40: 37.6 | U40: 89.53 | V40: TRUE | W40: Moderate Trust
...

Sheet Raw_Data
A1: ai_model_name | B1: query_category | C1: ai_confidence_percentage | D1: response_character_count | E1: has_cited_sources | F1: contains_hedging_words | G1: includes_disclaimer | H1: answer_detail_level | I1: respondent_age_bracket | J1: education_level | K1: digital_literacy_score | L1: ai_familiarity_level | M1: decision_importance | N1: urgency_level | O1: belief_alignment_status | P1: subject_matter_expertise | Q1: trust_score_out_of_10 | R1: performed_fact_check | S1: fact_check_method_used | T1: verification_duration_mins | U1: answer_accuracy_percentage | V1: trust_calibration_valid | W1: user_skepticism_category
A2: Claude | B2: math_calculation | C2: 93.23 | D2: 527 | E2: TRUE | F2: FALSE | G2: FALSE | H2: Moderate | I2: 45-54 | J2: Bachelors | K2: Low | L2: Intermediate | M2: Low | N2: Low | O2: FALSE | P2: FALSE | Q2: 10 | R2: TRUE | S2: Google Search | T2: 10.7 | U2: 80.15 | V2: TRUE | W2: Moderate Trust
A3: Llama | B3: recipe_cooking | C3: 84.47 | D3: 581 | E3: FALSE | F3: FALSE | G3: FALSE | H3: Specific | I3: 55-64 | J3: PhD | K3: Expert | L3: First Time | M3: High | O3: FALSE | P3: TRUE | Q3: 7.9 | R3: TRUE | S3: Asked Expert | T3: 44.3 | U3: 92.33 | V3: TRUE | W3: Skeptical
A4: Claude | B4: general_knowledge | C4: 69.82 | D4: 484 | E4: TRUE | F4: TRUE | G4: FALSE | H4: Very Specific | I4: 35-44 | J4: High School | K4: Medium | L4: Intermediate | M4: Critical | O4: TRUE | P4: FALSE | Q4: 8.6 | R4: TRUE | S4: Consulted Documentation | T4: 37.5 | U4: 67.32 | V4: TRUE | W4: Moderate Trust
A5: Claude | B5: creative_writing | C5: 79.61 | D5: 73 | E5: TRUE | F5: TRUE | G5: FALSE | H5: Specific | I5: 45-54 | J5: Professional | K5: Low | L5: Advanced | M5: High | P5: FALSE | Q5: 8.9 | R5: TRUE | S5: Checked Official Source | T5: 22.7 | U5: 73.12 | V5: TRUE | W5: Moderate Trust
A6: Claude | B6: creative_writing | C6: 67.71 | D6: 146 | E6: FALSE | F6: TRUE | G6: FALSE | H6: Vague | I6: 55-64 | J6: Masters | K6: Low | L6: Expert | M6: Low | O6: TRUE | P6: TRUE | Q6: 9 | R6: TRUE | S6: Academic Paper | T6: 43.7 | U6: 81.05 | V6: TRUE | W6: Moderate Trust
A7: Mistral | B7: math_calculation | C7: 93.41 | D7: 198 | E7: FALSE | F7: TRUE | G7: FALSE | H7: Moderate | I7: 18-24 | J7: Professional | K7: Expert | L7: Advanced | M7: Medium | O7: FALSE | P7: FALSE | Q7: 8.2 | R7: FALSE | T7: 0 | U7: 100 | V7: TRUE | W7: Blind Trust
A8: Claude | B8: technical_coding | C8: 75.87 | D8: 285 | E8: FALSE | F8: FALSE | G8: TRUE | H8: Very Specific | I8: 18-24 | J8: High School | K8: Expert | L8: Expert | M8: Low | N8: High | O8: FALSE | P8: TRUE | Q8: 7.6 | R8: FALSE | T8: 0 | U8: 79.04 | V8: TRUE | W8: Moderate Trust
A9: Claude | B9: financial_advice | C9: 57.32 | D9: 371 | E9: TRUE | F9: FALSE | G9: FALSE | H9: Vague | I9: 55-64 | J9: Professional | K9: Medium | L9: First Time | M9: Critical | N9: High | P9: FALSE | Q9: 6.4 | R9: FALSE | T9: 0 | U9: 55.65 | V9: TRUE | W9: Moderate Trust
A10: ChatGPT-3.5 | B10: medical_advice | C10: 50.17 | D10: 344 | E10: FALSE | F10: FALSE | G10: TRUE | H10: Vague | I10: 65+ | J10: PhD | K10: Medium | L10: Advanced | M10: Medium | N10: High | P10: FALSE | Q10: 5.3 | R10: TRUE | S10: Personal Testing | T10: 20 | U10: 41.69 | V10: TRUE | W10: Skeptical
A11: Llama | B11: medical_advice | C11: 58.77 | D11: 63 | E11: FALSE | F11: FALSE | G11: TRUE | H11: Vague | I11: 65+ | J11: Professional | K11: Low | L11: Expert | M11: Medium | N11: Low | O11: FALSE | P11: FALSE | Q11: 5.6 | R11: TRUE | S11: Cross-referenced Multiple AIs | T11: 23.5 | U11: 50.81 | V11: TRUE | W11: Skeptical
A12: Claude | B12: general_knowledge | C12: 82.85 | D12: 331 | E12: TRUE | F12: TRUE | G12: TRUE | H12: Specific | I12: 45-54 | J12: Masters | K12: Expert | L12: First Time | M12: Medium | N12: Medium | P12: TRUE | Q12: 10 | R12: TRUE | S12: Academic Paper | T12: 22.9 | U12: 68.05 | V12: FALSE | W12: Moderate Trust
A13: Claude | B13: recipe_cooking | C13: 76.69 | D13: 70 | E13: TRUE | F13: FALSE | G13: TRUE | H13: Moderate | I13: 18-24 | J13: Professional | K13: Low | L13: Expert | M13: Low | N13: Medium | P13: TRUE | Q13: 9.9 | R13: FALSE | T13: 0 | U13: 62.11 | V13: FALSE | W13: Blind Trust
A14: Llama | B14: current_events | C14: 77.43 | D14: 549 | E14: FALSE | F14: FALSE | G14: TRUE | H14: Vague | I14: 25-34 | J14: PhD | K14: High | L14: Advanced | M14: Low | N14: Medium | O14: TRUE | P14: FALSE | Q14: 9.5 | R14: TRUE | S14: Checked Official Source | T14: 33.8 | U14: 73.81 | V14: FALSE | W14: Moderate Trust
A15: Gemini | B15: recipe_cooking | C15: 78.83 | D15: 419 | E15: FALSE | F15: TRUE | G15: FALSE | H15: Specific | I15: 35-44 | J15: High School | K15: Expert | L15: Advanced | M15: Medium | N15: Medium | P15: FALSE | Q15: 7.2 | R15: TRUE | S15: Cross-referenced Multiple AIs | T15: 41.9 | U15: 81.22 | V15: TRUE | W15: Skeptical
A16: Gemini | B16: creative_writing | C16: 75 | D16: 386 | E16: FALSE | F16: TRUE | G16: TRUE | H16: Moderate | I16: 45-54 | J16: Professional | K16: Medium | L16: Intermediate | M16: Low | N16: Medium | O16: TRUE | P16: FALSE | Q16: 9.9 | R16: FALSE | T16: 0 | U16: 66.21 | V16: FALSE | W16: Blind Trust
A17: Gemini | B17: current_events | C17: 55.73 | D17: 698 | E17: TRUE | F17: TRUE | G17: FALSE | H17: Moderate | I17: 18-24 | J17: Bachelors | K17: Low | L17: Beginner | M17: Critical | N17: High | O17: FALSE | P17: TRUE | Q17: 5.2 | R17: FALSE | T17: 0 | U17: 55.92 | V17: TRUE | W17: Skeptical
A18: Gemini | B18: factual_historical | C18: 79.42 | D18: 382 | E18: FALSE | F18: FALSE | G18: TRUE | H18: Vague | I18: 18-24 | J18: Professional | K18: Expert | L18: Advanced | M18: High | N18: High | O18: FALSE | P18: FALSE | Q18: 6.7 | R18: TRUE | S18: Asked Expert | T18: 30 | U18: 88.58 | V18: FALSE | W18: Skeptical
A19: Claude | B19: opinion_based | C19: 47.7 | D19: 53 | E19: FALSE | F19: TRUE | G19: FALSE | H19: Vague | I19: 65+ | J19: PhD | K19: High | L19: Beginner | M19: Critical | N19: Low | O19: FALSE | P19: TRUE | Q19: 2.9 | R19: TRUE | S19: Academic Paper | T19: 29.9 | U19: 40.41 | V19: TRUE | W19: Highly Skeptical
A20: ChatGPT-3.5 | B20: legal_advice | C20: 52.94 | D20: 725 | E20: TRUE | F20: FALSE | G20: TRUE | H20: Vague | I20: 55-64 | J20: PhD | K20: Medium | L20: Intermediate | M20: Critical | N20: Medium | O20: FALSE | P20: TRUE | Q20: 4.7 | R20: TRUE | S20: Personal Testing | T20: 36.1 | U20: 38.72 | V20: TRUE | W20: Highly Skeptical
A21: Gemini | B21: technical_coding | C21: 91.49 | D21: 457 | E21: TRUE | F21: TRUE | G21: FALSE | H21: Very Specific | I21: 35-44 | J21: Masters | K21: Expert | L21: Advanced | M21: Medium | N21: Low | P21: TRUE | Q21: 9.4 | R21: FALSE | T21: 0 | U21: 78.01 | V21: TRUE | W21: Blind Trust
A22: Llama | B22: recipe_cooking | C22: 85.85 | D22: 617 | E22: FALSE | F22: TRUE | G22: FALSE | H22: Specific | I22: 55-64 | J22: Bachelors | K22: Low | L22: Beginner | M22: Low | N22: Low | P22: FALSE | Q22: 9.9 | R22: TRUE | S22: Cross-referenced Multiple AIs | T22: 42.1 | U22: 77.63 | V22: FALSE | W22: Moderate Trust
A23: Claude | B23: financial_advice | C23: 55.95 | D23: 166 | E23: TRUE | F23: FALSE | G23: TRUE | H23: Very Specific | I23: 18-24 | J23: Masters | K23: Medium | L23: First Time | M23: High | N23: High | P23: TRUE | Q23: 7.7 | R23: TRUE | S23: Checked Official Source | T23: 34.3 | U23: 55.71 | V23: FALSE | W23: Skeptical
A24: Mistral | B24: current_events | C24: 75.51 | D24: 289 | E24: TRUE | F24: FALSE | G24: TRUE | H24: Specific | I24: 45-54 | J24: Masters | K24: Low | L24: First Time | M24: High | N24: Low | O24: TRUE | P24: TRUE | Q24: 10 | R24: TRUE | S24: Google Search | T24: 13 | U24: 53.58 | V24: FALSE | W24: Moderate Trust
A25: Llama | B25: opinion_based | C25: 42.81 | D25: 86 | E25: TRUE | F25: FALSE | G25: TRUE | H25: Very Specific | I25: 45-54 | J25: Masters | K25: Low | L25: Intermediate | M25: Critical | N25: High | O25: FALSE | P25: FALSE | Q25: 2.7 | R25: TRUE | S25: Academic Paper | T25: 2.5 | U25: 21.4 | V25: TRUE | W25: Highly Skeptical
A26: GPT-4 | B26: current_events | C26: 62.31 | D26: 51 | E26: FALSE | F26: TRUE | G26: TRUE | H26: Very Specific | I26: 65+ | J26: PhD | K26: Low | L26: Beginner | M26: High | N26: Low | O26: FALSE | P26: FALSE | Q26: 4.8 | R26: TRUE | S26: Cross-referenced Multiple AIs | T26: 26.2 | U26: 40.83 | V26: TRUE | W26: Highly Skeptical
A27: GPT-4 | B27: current_events | C27: 65.12 | D27: 320 | E27: FALSE | F27: TRUE | G27: TRUE | H27: Very Specific | I27: 18-24 | J27: PhD | K27: Expert | L27: Beginner | M27: High | O27: TRUE | P27: FALSE | Q27: 7.5 | R27: TRUE | S27: Personal Testing | T27: 11.5 | U27: 61.68 | V27: TRUE | W27: Skeptical
A28: Claude | B28: legal_advice | C28: 64.2 | D28: 293 | E28: TRUE | F28: FALSE | G28: FALSE | H28: Specific | I28: 65+ | J28: PhD | K28: High | L28: Expert | M28: Low | N28: High | O28: FALSE | P28: FALSE | Q28: 6.6 | R28: TRUE | S28: Google Search | T28: 27.5 | U28: 59.63 | V28: TRUE | W28: Skeptical
A29: Claude | B29: creative_writing | C29: 64.93 | D29: 177 | E29: TRUE | F29: FALSE | G29: FALSE | H29: Very Specific | I29: 65+ | J29: Masters | K29: Low | L29: Advanced | M29: Low | N29: Low | O29: TRUE | P29: FALSE | Q29: 9.4 | R29: TRUE | S29: Checked Official Source | T29: 30.4 | U29: 67.76 | V29: FALSE | W29: Moderate Trust
A30: Gemini | B30: technical_coding | C30: 75.1 | D30: 107 | E30: FALSE | F30: FALSE | G30: TRUE | H30: Moderate | I30: 65+ | J30: PhD | K30: Expert | L30: Beginner | M30: High | O30: TRUE | P30: TRUE | Q30: 9.5 | R30: TRUE | S30: Consulted Documentation | T30: 37.6 | U30: 69.68 | V30: FALSE | W30: Moderate Trust
A31: ChatGPT-3.5 | B31: opinion_based | C31: 43.22 | D31: 345 | E31: TRUE | F31: TRUE | G31: TRUE | H31: Moderate | I31: 35-44 | J31: High School | K31: Low | L31: Intermediate | M31: High | N31: Medium | O31: FALSE | P31: FALSE | Q31: 4.3 | R31: FALSE | T31: 0 | U31: 26.69 | V31: TRUE | W31: Skeptical
A32: Gemini | B32: legal_advice | C32: 58.29 | D32: 776 | E32: TRUE | F32: FALSE | G32: TRUE | H32: Vague | I32: 65+ | J32: PhD | K32: Low | L32: First Time | M32: Low | N32: High | O32: TRUE | P32: TRUE | Q32: 10 | R32: FALSE | T32: 0 | U32: 63.76 | V32: FALSE | W32: Blind Trust
A33: Llama | B33: current_events | C33: 76.42 | D33: 466 | E33: TRUE | F33: FALSE | G33: FALSE | H33: Moderate | I33: 35-44 | J33: Masters | K33: Expert | L33: Expert | M33: Critical | O33: TRUE | P33: TRUE | Q33: 9.4 | R33: TRUE | S33: Google Search | T33: 30.9 | U33: 66.39 | V33: FALSE | W33: Moderate Trust
A34: Gemini | B34: financial_advice | C34: 48.76 | D34: 60 | E34: FALSE | F34: TRUE | G34: TRUE | H34: Moderate | I34: 65+ | J34: Bachelors | K34: Medium | L34: Beginner | M34: Medium | N34: Low | O34: TRUE | P34: FALSE | Q34: 7.3 | R34: TRUE | S34: Checked Official Source | T34: 26.3 | U34: 47.61 | V34: FALSE | W34: Skeptical
A35: GPT-4 | B35: math_calculation | C35: 92.82 | D35: 541 | E35: TRUE | F35: FALSE | G35: FALSE | H35: Moderate | I35: 65+ | J35: High School | K35: Medium | L35: Beginner | M35: Medium | P35: FALSE | Q35: 10 | R35: FALSE | T35: 0 | U35: 90.77 | V35: TRUE | W35: Blind Trust
A36: Mistral | B36: financial_advice | C36: 46.95 | D36: 521 | E36: FALSE | F36: FALSE | G36: FALSE | H36: Vague | I36: 55-64 | J36: High School | K36: Expert | L36: Intermediate | M36: Low | P36: FALSE | Q36: 5.2 | R36: TRUE | S36: Academic Paper | T36: 25.5 | U36: 58.55 | V36: TRUE | W36: Skeptical
A37: Claude | B37: creative_writing | C37: 60.77 | D37: 442 | E37: TRUE | F37: TRUE | G37: TRUE | H37: Moderate | I37: 35-44 | J37: High School | K37: Expert | L37: Beginner | M37: Low | N37: Low | P37: FALSE | Q37: 8 | R37: TRUE | S37: Personal Testing | T37: 35 | U37: 71.84 | V37: TRUE | W37: Moderate Trust
A38: Claude | B38: financial_advice | C38: 56.58 | D38: 688 | E38: FALSE | F38: TRUE | G38: FALSE | H38: Moderate | I38: 35-44 | J38: High School | K38: Expert | L38: First Time | M38: Medium | P38: TRUE | Q38: 5.7 | R38: TRUE | S38: Google Search | T38: 14.8 | U38: 48.42 | V38: TRUE | W38: Skeptical
A39: Claude | B39: math_calculation | C39: 98.66 | D39: 109 | E39: FALSE | F39: TRUE | G39: TRUE | H39: Specific | I39: 45-54 | J39: Professional | K39: High | L39: Beginner | M39: Medium | O39: FALSE | P39: TRUE | Q39: 9.1 | R39: TRUE | S39: Cross-referenced Multiple AIs | T39: 16.6 | U39: 89.95 | V39: TRUE | W39: Moderate Trust
A40: Claude | B40: math_calculation | C40: 89.07 | D40: 258 | E40: FALSE | F40: FALSE | G40: TRUE | H40: Very Specific | I40: 55-64 | J40: Masters | K40: Expert | L40: Expert | M40: High | N40: Medium | O40: TRUE | P40: FALSE | Q40: 10 | R40: TRUE | S40: Asked Colleague | T40: 37.6 | U40: 89.53 | V40: TRUE | W40: Moderate Trust
...

Sheet Clean_Data
A1: ai_model_name | B1: query_category | C1: ai_confidence_percentage | D1: response_character_count | E1: has_cited_sources | F1: contains_hedging_words | G1: includes_disclaimer | H1: answer_detail_level | I1: respondent_age_bracket | J1: education_level | K1: digital_literacy_score | L1: ai_familiarity_level | M1: decision_importance | N1: urgency_level | O1: belief_alignment_status | P1: subject_matter_expertise | Q1: trust_score_out_of_10 | R1: performed_fact_check | S1: fact_check_method_used | T1: verification_duration_mins | U1: answer_accuracy_percentage | V1: trust_calibration_valid | W1: user_skepticism_category | AA1: Cleaning | AC1: Missing Value | AE1: contains_hedging_words | AF1: urgency_level | AG1: belief_alignment_status | AH1: fact_check_method_used | AJ1: Create Trust Category | AL1: Round Accuracy | AM1: C Education
A2: Claude | B2: math_calculation | C2: 93.23 | D2: 527 | E2: TRUE | F2: FALSE | G2: FALSE | H2: Moderate | I2: 45-54 | J2: Bachelors | K2: Low | L2: Intermediate | M2: Low | N2: Low | O2: FALSE | P2: FALSE | Q2: 10 | R2: TRUE | S2: Google Search | T2: 10.7 | U2: 80.15 | V2: TRUE | W2: Moderate Trust | AC2: Convert TRUE/FALSE to Yes/No | AE2: =IF(F2=TRUE,"Yes","No") -> No | AF2: =IF(ISBLANK(N2),"Unknown",N2) -> Low | AG2: =IF(O2=TRUE,"Yes","No") -> No | AH2: =IF(ISBLANK(S2),"Unknown",S2) -> Google Search | AJ2: =IF(Q2>=8,"High Trust", IF(Q3>=5,"Moderate Trust","Low Trust")) -> High Trust | AL2: =ROUND(U2,1) -> 80.2 | AM2: =TRIM(J2) -> Bachelors
A3: Llama | B3: recipe_cooking | C3: 84.47 | D3: 581 | E3: FALSE | F3: FALSE | G3: FALSE | H3: Specific | I3: 55-64 | J3: PhD | K3: Expert | L3: First Time | M3: High | O3: FALSE | P3: TRUE | Q3: 7.9 | R3: TRUE | S3: Asked Expert | T3: 44.3 | U3: 92.33 | V3: TRUE | W3: Skeptical | AE3: =IF(F3=TRUE,"Yes","No") -> No | AF3: =IF(ISBLANK(N3),"Unknown",N3) -> Unknown | AG3: =IF(O3=TRUE,"Yes","No") -> No | AH3: =IF(ISBLANK(S3),"Unknown",S3) -> Asked Expert | AJ3: =IF(Q3>=8,"High Trust", IF(Q4>=5,"Moderate Trust","Low Trust")) -> Moderate Trust | AL3: =ROUND(U3,1) -> 92.3 | AM3: =TRIM(J3) -> PhD
A4: Claude | B4: general_knowledge | C4: 69.82 | D4: 484 | E4: TRUE | F4: TRUE | G4: FALSE | H4: Very Specific | I4: 35-44 | J4: High School | K4: Medium | L4: Intermediate | M4: Critical | O4: TRUE | P4: FALSE | Q4: 8.6 | R4: TRUE | S4: Consulted Documentation | T4: 37.5 | U4: 67.32 | V4: TRUE | W4: Moderate Trust | AE4: =IF(F4=TRUE,"Yes","No") -> Yes | AF4: =IF(ISBLANK(N4),"Unknown",N4) -> Unknown | AG4: =IF(O4=TRUE,"Yes","No") -> Yes | AH4: =IF(ISBLANK(S4),"Unknown",S4) -> Consulted Documentation | AJ4: =IF(Q4>=8,"High Trust", IF(Q5>=5,"Moderate Trust","Low Trust")) -> High Trust | AL4: =ROUND(U4,1) -> 67.3 | AM4: =TRIM(J4) -> High School
A5: Claude | B5: creative_writing | C5: 79.61 | D5: 73 | E5: TRUE | F5: TRUE | G5: FALSE | H5: Specific | I5: 45-54 | J5: Professional | K5: Low | L5: Advanced | M5: High | P5: FALSE | Q5: 8.9 | R5: TRUE | S5: Checked Official Source | T5: 22.7 | U5: 73.12 | V5: TRUE | W5: Moderate Trust | AE5: =IF(F5=TRUE,"Yes","No") -> Yes | AF5: =IF(ISBLANK(N5),"Unknown",N5) -> Unknown | AG5: =IF(O5=TRUE,"Yes","No") -> No | AH5: =IF(ISBLANK(S5),"Unknown",S5) -> Checked Official Source | AJ5: =IF(Q5>=8,"High Trust", IF(Q6>=5,"Moderate Trust","Low Trust")) -> High Trust | AL5: =ROUND(U5,1) -> 73.1 | AM5: =TRIM(J5) -> Professional
A6: Claude | B6: creative_writing | C6: 67.71 | D6: 146 | E6: FALSE | F6: TRUE | G6: FALSE | H6: Vague | I6: 55-64 | J6: Masters | K6: Low | L6: Expert | M6: Low | O6: TRUE | P6: TRUE | Q6: 9 | R6: TRUE | S6: Academic Paper | T6: 43.7 | U6: 81.05 | V6: TRUE | W6: Moderate Trust | AE6: =IF(F6=TRUE,"Yes","No") -> Yes | AF6: =IF(ISBLANK(N6),"Unknown",N6) -> Unknown | AG6: =IF(O6=TRUE,"Yes","No") -> Yes | AH6: =IF(ISBLANK(S6),"Unknown",S6) -> Academic Paper | AJ6: =IF(Q6>=8,"High Trust", IF(Q7>=5,"Moderate Trust","Low Trust")) -> High Trust | AL6: =ROUND(U6,1) -> 81.1 | AM6: =TRIM(J6) -> Masters
A7: Mistral | B7: math_calculation | C7: 93.41 | D7: 198 | E7: FALSE | F7: TRUE | G7: FALSE | H7: Moderate | I7: 18-24 | J7: Professional | K7: Expert | L7: Advanced | M7: Medium | O7: FALSE | P7: FALSE | Q7: 8.2 | R7: FALSE | T7: 0 | U7: 100 | V7: TRUE | W7: Blind Trust | AE7: =IF(F7=TRUE,"Yes","No") -> Yes | AF7: =IF(ISBLANK(N7),"Unknown",N7) -> Unknown | AG7: =IF(O7=TRUE,"Yes","No") -> No | AH7: =IF(ISBLANK(S7),"Unknown",S7) -> Unknown | AJ7: =IF(Q7>=8,"High Trust", IF(Q8>=5,"Moderate Trust","Low Trust")) -> High Trust | AL7: =ROUND(U7,1) -> 100 | AM7: =TRIM(J7) -> Professional
A8: Claude | B8: technical_coding | C8: 75.87 | D8: 285 | E8: FALSE | F8: FALSE | G8: TRUE | H8: Very Specific | I8: 18-24 | J8: High School | K8: Expert | L8: Expert | M8: Low | N8: High | O8: FALSE | P8: TRUE | Q8: 7.6 | R8: FALSE | T8: 0 | U8: 79.04 | V8: TRUE | W8: Moderate Trust | AE8: =IF(F8=TRUE,"Yes","No") -> No | AF8: =IF(ISBLANK(N8),"Unknown",N8) -> High | AG8: =IF(O8=TRUE,"Yes","No") -> No | AH8: =IF(ISBLANK(S8),"Unknown",S8) -> Unknown | AJ8: =IF(Q8>=8,"High Trust", IF(Q9>=5,"Moderate Trust","Low Trust")) -> Moderate Trust | AL8: =ROUND(U8,1) -> 79 | AM8: =TRIM(J8) -> High School
A9: Claude | B9: financial_advice | C9: 57.32 | D9: 371 | E9: TRUE | F9: FALSE | G9: FALSE | H9: Vague | I9: 55-64 | J9: Professional | K9: Medium | L9: First Time | M9: Critical | N9: High | P9: FALSE | Q9: 6.4 | R9: FALSE | T9: 0 | U9: 55.65 | V9: TRUE | W9: Moderate Trust | AE9: =IF(F9=TRUE,"Yes","No") -> No | AF9: =IF(ISBLANK(N9),"Unknown",N9) -> High | AG9: =IF(O9=TRUE,"Yes","No") -> No | AH9: =IF(ISBLANK(S9),"Unknown",S9) -> Unknown | AJ9: =IF(Q9>=8,"High Trust", IF(Q10>=5,"Moderate Trust","Low Trust")) -> Moderate Trust | AL9: =ROUND(U9,1) -> 55.7 | AM9: =TRIM(J9) -> Professional
A10: ChatGPT-3.5 | B10: medical_advice | C10: 50.17 | D10: 344 | E10: FALSE | F10: FALSE | G10: TRUE | H10: Vague | I10: 65+ | J10: PhD | K10: Medium | L10: Advanced | M10: Medium | N10: High | P10: FALSE | Q10: 5.3 | R10: TRUE | S10: Personal Testing | T10: 20 | U10: 41.69 | V10: TRUE | W10: Skeptical | AE10: =IF(F10=TRUE,"Yes","No") -> No | AF10: =IF(ISBLANK(N10),"Unknown",N10) -> High | AG10: =IF(O10=TRUE,"Yes","No") -> No | AH10: =IF(ISBLANK(S10),"Unknown",S10) -> Personal Testing | AJ10: =IF(Q10>=8,"High Trust", IF(Q11>=5,"Moderate Trust","Low Trust")) -> Moderate Trust | AL10: =ROUND(U10,1) -> 41.7 | AM10: =TRIM(J10) -> PhD
A11: Llama | B11: medical_advice | C11: 58.77 | D11: 63 | E11: FALSE | F11: FALSE | G11: TRUE | H11: Vague | I11: 65+ | J11: Professional | K11: Low | L11: Expert | M11: Medium | N11: Low | O11: FALSE | P11: FALSE | Q11: 5.6 | R11: TRUE | S11: Cross-referenced Multiple AIs | T11: 23.5 | U11: 50.81 | V11: TRUE | W11: Skeptical | AE11: =IF(F11=TRUE,"Yes","No") -> No | AF11: =IF(ISBLANK(N11),"Unknown",N11) -> Low | AG11: =IF(O11=TRUE,"Yes","No") -> No | AH11: =IF(ISBLANK(S11),"Unknown",S11) -> Cross-referenced Multiple AIs | AJ11: =IF(Q11>=8,"High Trust", IF(Q12>=5,"Moderate Trust","Low Trust")) -> Moderate Trust | AL11: =ROUND(U11,1) -> 50.8 | AM11: =TRIM(J11) -> Professional
A12: Claude | B12: general_knowledge | C12: 82.85 | D12: 331 | E12: TRUE | F12: TRUE | G12: TRUE | H12: Specific | I12: 45-54 | J12: Masters | K12: Expert | L12: First Time | M12: Medium | N12: Medium | P12: TRUE | Q12: 10 | R12: TRUE | S12: Academic Paper | T12: 22.9 | U12: 68.05 | V12: FALSE | W12: Moderate Trust | AE12: =IF(F12=TRUE,"Yes","No") -> Yes | AF12: =IF(ISBLANK(N12),"Unknown",N12) -> Medium | AG12: =IF(O12=TRUE,"Yes","No") -> No | AH12: =IF(ISBLANK(S12),"Unknown",S12) -> Academic Paper | AJ12: =IF(Q12>=8,"High Trust", IF(Q13>=5,"Moderate Trust","Low Trust")) -> High Trust | AL12: =ROUND(U12,1) -> 68.1 | AM12: =TRIM(J12) -> Masters
A13: Claude | B13: recipe_cooking | C13: 76.69 | D13: 70 | E13: TRUE | F13: FALSE | G13: TRUE | H13: Moderate | I13: 18-24 | J13: Professional | K13: Low | L13: Expert | M13: Low | N13: Medium | P13: TRUE | Q13: 9.9 | R13: FALSE | T13: 0 | U13: 62.11 | V13: FALSE | W13: Blind Trust | AE13: =IF(F13=TRUE,"Yes","No") -> No | AF13: =IF(ISBLANK(N13),"Unknown",N13) -> Medium | AG13: =IF(O13=TRUE,"Yes","No") -> No | AH13: =IF(ISBLANK(S13),"Unknown",S13) -> Unknown | AJ13: =IF(Q13>=8,"High Trust", IF(Q14>=5,"Moderate Trust","Low Trust")) -> High Trust | AL13: =ROUND(U13,1) -> 62.1 | AM13: =TRIM(J13) -> Professional
A14: Llama | B14: current_events | C14: 77.43 | D14: 549 | E14: FALSE | F14: FALSE | G14: TRUE | H14: Vague | I14: 25-34 | J14: PhD | K14: High | L14: Advanced | M14: Low | N14: Medium | O14: TRUE | P14: FALSE | Q14: 9.5 | R14: TRUE | S14: Checked Official Source | T14: 33.8 | U14: 73.81 | V14: FALSE | W14: Moderate Trust | AE14: =IF(F14=TRUE,"Yes","No") -> No | AF14: =IF(ISBLANK(N14),"Unknown",N14) -> Medium | AG14: =IF(O14=TRUE,"Yes","No") -> Yes | AH14: =IF(ISBLANK(S14),"Unknown",S14) -> Checked Official Source | AJ14: =IF(Q14>=8,"High Trust", IF(Q15>=5,"Moderate Trust","Low Trust")) -> High Trust | AL14: =ROUND(U14,1) -> 73.8 | AM14: =TRIM(J14) -> PhD
A15: Gemini | B15: recipe_cooking | C15: 78.83 | D15: 419 | E15: FALSE | G15: FALSE | H15: Specific | I15: 35-44 | J15: High School | K15: Expert | L15: Advanced | M15: Medium | N15: Medium | P15: FALSE | Q15: 7.2 | R15: TRUE | S15: Cross-referenced Multiple AIs | T15: 41.9 | U15: 81.22 | V15: TRUE | W15: Skeptical | AE15: =IF(F15=TRUE,"Yes","No") -> No | AF15: =IF(ISBLANK(N15),"Unknown",N15) -> Medium | AG15: =IF(O15=TRUE,"Yes","No") -> No | AH15: =IF(ISBLANK(S15),"Unknown",S15) -> Cross-referenced Multiple AIs | AJ15: =IF(Q15>=8,"High Trust", IF(Q16>=5,"Moderate Trust","Low Trust")) -> Moderate Trust | AL15: =ROUND(U15,1) -> 81.2 | AM15: =TRIM(J15) -> High School
A16: Gemini | B16: creative_writing | C16: 75 | D16: 386 | E16: FALSE | F16: TRUE | G16: TRUE | H16: Moderate | I16: 45-54 | J16: Professional | K16: Medium | L16: Intermediate | M16: Low | N16: Medium | O16: TRUE | P16: FALSE | Q16: 9.9 | R16: FALSE | T16: 0 | U16: 66.21 | V16: FALSE | W16: Blind Trust | AE16: =IF(F16=TRUE,"Yes","No") -> Yes | AF16: =IF(ISBLANK(N16),"Unknown",N16) -> Medium | AG16: =IF(O16=TRUE,"Yes","No") -> Yes | AH16: =IF(ISBLANK(S16),"Unknown",S16) -> Unknown | AJ16: =IF(Q16>=8,"High Trust", IF(Q17>=5,"Moderate Trust","Low Trust")) -> High Trust | AL16: =ROUND(U16,1) -> 66.2 | AM16: =TRIM(J16) -> Professional
A17: Gemini | B17: current_events | C17: 55.73 | D17: 698 | E17: TRUE | F17: TRUE | G17: FALSE | H17: Moderate | I17: 18-24 | J17: Bachelors | K17: Low | L17: Beginner | M17: Critical | N17: High | O17: FALSE | P17: TRUE | Q17: 5.2 | R17: FALSE | T17: 0 | U17: 55.92 | V17: TRUE | W17: Skeptical | AE17: =IF(F17=TRUE,"Yes","No") -> Yes | AF17: =IF(ISBLANK(N17),"Unknown",N17) -> High | AG17: =IF(O17=TRUE,"Yes","No") -> No | AH17: =IF(ISBLANK(S17),"Unknown",S17) -> Unknown | AJ17: =IF(Q17>=8,"High Trust", IF(Q18>=5,"Moderate Trust","Low Trust")) -> Moderate Trust | AL17: =ROUND(U17,1) -> 55.9 | AM17: =TRIM(J17) -> Bachelors
A18: Gemini | B18: factual_historical | C18: 79.42 | D18: 382 | E18: FALSE | F18: FALSE | G18: TRUE | H18: Vague | I18: 18-24 | J18: Professional | K18: Expert | L18: Advanced | M18: High | N18: High | O18: FALSE | P18: FALSE | Q18: 6.7 | R18: TRUE | S18: Asked Expert | T18: 30 | U18: 88.58 | V18: FALSE | W18: Skeptical | AE18: =IF(F18=TRUE,"Yes","No") -> No | AF18: =IF(ISBLANK(N18),"Unknown",N18) -> High | AG18: =IF(O18=TRUE,"Yes","No") -> No | AH18: =IF(ISBLANK(S18),"Unknown",S18) -> Asked Expert | AJ18: =IF(Q18>=8,"High Trust", IF(Q19>=5,"Moderate Trust","Low Trust")) -> Low Trust | AL18: =ROUND(U18,1) -> 88.6 | AM18: =TRIM(J18) -> Professional
A19: Claude | B19: opinion_based | C19: 47.7 | D19: 53 | E19: FALSE | F19: TRUE | G19: FALSE | H19: Vague | I19: 65+ | J19: PhD | K19: High | L19: Beginner | M19: Critical | N19: Low | O19: FALSE | P19: TRUE | Q19: 2.9 | R19: TRUE | S19: Academic Paper | T19: 29.9 | U19: 40.41 | V19: TRUE | W19: Highly Skeptical | AE19: =IF(F19=TRUE,"Yes","No") -> Yes | AF19: =IF(ISBLANK(N19),"Unknown",N19) -> Low | AG19: =IF(O19=TRUE,"Yes","No") -> No | AH19: =IF(ISBLANK(S19),"Unknown",S19) -> Academic Paper | AJ19: =IF(Q19>=8,"High Trust", IF(Q20>=5,"Moderate Trust","Low Trust")) -> Low Trust | AL19: =ROUND(U19,1) -> 40.4 | AM19: =TRIM(J19) -> PhD
A20: ChatGPT-3.5 | B20: legal_advice | C20: 52.94 | D20: 725 | E20: TRUE | F20: FALSE | G20: TRUE | H20: Vague | I20: 55-64 | J20: PhD | K20: Medium | L20: Intermediate | M20: Critical | N20: Medium | O20: FALSE | P20: TRUE | Q20: 4.7 | R20: TRUE | S20: Personal Testing | T20: 36.1 | U20: 38.72 | V20: TRUE | W20: Highly Skeptical | AE20: =IF(F20=TRUE,"Yes","No") -> No | AF20: =IF(ISBLANK(N20),"Unknown",N20) -> Medium | AG20: =IF(O20=TRUE,"Yes","No") -> No | AH20: =IF(ISBLANK(S20),"Unknown",S20) -> Personal Testing | AJ20: =IF(Q20>=8,"High Trust", IF(Q21>=5,"Moderate Trust","Low Trust")) -> Moderate Trust | AL20: =ROUND(U20,1) -> 38.7 | AM20: =TRIM(J20) -> PhD
A21: Gemini | B21: technical_coding | C21: 91.49 | D21: 457 | E21: TRUE | F21: TRUE | G21: FALSE | H21: Very Specific | I21: 35-44 | J21: Masters | K21: Expert | L21: Advanced | M21: Medium | N21: Low | P21: TRUE | Q21: 9.4 | R21: FALSE | T21: 0 | U21: 78.01 | V21: TRUE | W21: Blind Trust | AE21: =IF(F21=TRUE,"Yes","No") -> Yes | AF21: =IF(ISBLANK(N21),"Unknown",N21) -> Low | AG21: =IF(O21=TRUE,"Yes","No") -> No | AH21: =IF(ISBLANK(S21),"Unknown",S21) -> Unknown | AJ21: =IF(Q21>=8,"High Trust", IF(Q22>=5,"Moderate Trust","Low Trust")) -> High Trust | AL21: =ROUND(U21,1) -> 78 | AM21: =TRIM(J21) -> Masters
A22: Llama | B22: recipe_cooking | C22: 85.85 | D22: 617 | E22: FALSE | F22: TRUE | G22: FALSE | H22: Specific | I22: 55-64 | J22: Bachelors | K22: Low | L22: Beginner | M22: Low | N22: Low | P22: FALSE | Q22: 9.9 | R22: TRUE | S22: Cross-referenced Multiple AIs | T22: 42.1 | U22: 77.63 | V22: FALSE | W22: Moderate Trust | AE22: =IF(F22=TRUE,"Yes","No") -> Yes | AF22: =IF(ISBLANK(N22),"Unknown",N22) -> Low | AG22: =IF(O22=TRUE,"Yes","No") -> No | AH22: =IF(ISBLANK(S22),"Unknown",S22) -> Cross-referenced Multiple AIs | AJ22: =IF(Q22>=8,"High Trust", IF(Q23>=5,"Moderate Trust","Low Trust")) -> High Trust | AL22: =ROUND(U22,1) -> 77.6 | AM22: =TRIM(J22) -> Bachelors
A23: Claude | B23: financial_advice | C23: 55.95 | D23: 166 | E23: TRUE | F23: FALSE | G23: TRUE | H23: Very Specific | I23: 18-24 | J23: Masters | K23: Medium | L23: First Time | M23: High | N23: High | P23: TRUE | Q23: 7.7 | R23: TRUE | S23: Checked Official Source | T23: 34.3 | U23: 55.71 | V23: FALSE | W23: Skeptical | AE23: =IF(F23=TRUE,"Yes","No") -> No | AF23: =IF(ISBLANK(N23),"Unknown",N23) -> High | AG23: =IF(O23=TRUE,"Yes","No") -> No | AH23: =IF(ISBLANK(S23),"Unknown",S23) -> Checked Official Source | AJ23: =IF(Q23>=8,"High Trust", IF(Q24>=5,"Moderate Trust","Low Trust")) -> Moderate Trust | AL23: =ROUND(U23,1) -> 55.7 | AM23: =TRIM(J23) -> Masters
A24: Mistral | B24: current_events | C24: 75.51 | D24: 289 | E24: TRUE | F24: FALSE | G24: TRUE | H24: Specific | I24: 45-54 | J24: Masters | K24: Low | L24: First Time | M24: High | N24: Low | O24: TRUE | P24: TRUE | Q24: 10 | R24: TRUE | S24: Google Search | T24: 13 | U24: 53.58 | V24: FALSE | W24: Moderate Trust | AE24: =IF(F24=TRUE,"Yes","No") -> No | AF24: =IF(ISBLANK(N24),"Unknown",N24) -> Low | AG24: =IF(O24=TRUE,"Yes","No") -> Yes | AH24: =IF(ISBLANK(S24),"Unknown",S24) -> Google Search | AJ24: =IF(Q24>=8,"High Trust", IF(Q25>=5,"Moderate Trust","Low Trust")) -> High Trust | AL24: =ROUND(U24,1) -> 53.6 | AM24: =TRIM(J24) -> Masters
A25: Llama | B25: opinion_based | C25: 42.81 | D25: 86 | E25: TRUE | F25: FALSE | G25: TRUE | H25: Very Specific | I25: 45-54 | J25: Masters | K25: Low | L25: Intermediate | M25: Critical | N25: High | O25: FALSE | P25: FALSE | Q25: 2.7 | R25: TRUE | S25: Academic Paper | T25: 2.5 | U25: 21.4 | V25: TRUE | W25: Highly Skeptical | AE25: =IF(F25=TRUE,"Yes","No") -> No | AF25: =IF(ISBLANK(N25),"Unknown",N25) -> High | AG25: =IF(O25=TRUE,"Yes","No") -> No | AH25: =IF(ISBLANK(S25),"Unknown",S25) -> Academic Paper | AJ25: =IF(Q25>=8,"High Trust", IF(Q26>=5,"Moderate Trust","Low Trust")) -> Low Trust | AL25: =ROUND(U25,1) -> 21.4 | AM25: =TRIM(J25) -> Masters | AP25: Column1
A26: GPT-4 | B26: current_events | C26: 62.31 | D26: 51 | E26: FALSE | F26: TRUE | G26: TRUE | H26: Very Specific | I26: 65+ | J26: PhD | K26: Low | L26: Beginner | M26: High | N26: Low | O26: FALSE | P26: FALSE | Q26: 4.8 | R26: TRUE | S26: Cross-referenced Multiple AIs | T26: 26.2 | U26: 40.83 | V26: TRUE | W26: Highly Skeptical | AE26: =IF(F26=TRUE,"Yes","No") -> Yes | AF26: =IF(ISBLANK(N26),"Unknown",N26) -> Low | AG26: =IF(O26=TRUE,"Yes","No") -> No | AH26: =IF(ISBLANK(S26),"Unknown",S26) -> Cross-referenced Multiple AIs | AJ26: =IF(Q26>=8,"High Trust", IF(Q27>=5,"Moderate Trust","Low Trust")) -> Moderate Trust | AL26: =ROUND(U26,1) -> 40.8 | AM26: =TRIM(J26) -> PhD
A27: GPT-4 | B27: current_events | C27: 65.12 | D27: 320 | E27: FALSE | F27: TRUE | G27: TRUE | H27: Very Specific | I27: 18-24 | J27: PhD | K27: Expert | L27: Beginner | M27: High | O27: TRUE | P27: FALSE | Q27: 7.5 | R27: TRUE | S27: Personal Testing | T27: 11.5 | U27: 61.68 | V27: TRUE | W27: Skeptical | AE27: =IF(F27=TRUE,"Yes","No") -> Yes | AF27: =IF(ISBLANK(N27),"Unknown",N27) -> Unknown | AG27: =IF(O27=TRUE,"Yes","No") -> Yes | AH27: =IF(ISBLANK(S27),"Unknown",S27) -> Personal Testing | AJ27: =IF(Q27>=8,"High Trust", IF(Q28>=5,"Moderate Trust","Low Trust")) -> Moderate Trust | AL27: =ROUND(U27,1) -> 61.7 | AM27: =TRIM(J27) -> PhD
A28: Claude | B28: legal_advice | C28: 64.2 | D28: 293 | E28: TRUE | F28: FALSE | G28: FALSE | H28: Specific | I28: 65+ | J28: PhD | K28: High | L28: Expert | M28: Low | N28: High | O28: FALSE | P28: FALSE | Q28: 6.6 | R28: TRUE | S28: Google Search | T28: 27.5 | U28: 59.63 | V28: TRUE | W28: Skeptical | AE28: =IF(F28=TRUE,"Yes","No") -> No | AF28: =IF(ISBLANK(N28),"Unknown",N28) -> High | AG28: =IF(O28=TRUE,"Yes","No") -> No | AH28: =IF(ISBLANK(S28),"Unknown",S28) -> Google Search | AJ28: =IF(Q28>=8,"High Trust", IF(Q29>=5,"Moderate Trust","Low Trust")) -> Moderate Trust | AL28: =ROUND(U28,1) -> 59.6 | AM28: =TRIM(J28) -> PhD
A29: Claude | B29: creative_writing | C29: 64.93 | D29: 177 | E29: TRUE | F29: FALSE | G29: FALSE | H29: Very Specific | I29: 65+ | J29: Masters | K29: Low | L29: Advanced | M29: Low | N29: Low | O29: TRUE | P29: FALSE | Q29: 9.4 | R29: TRUE | S29: Checked Official Source | T29: 30.4 | U29: 67.76 | V29: FALSE | W29: Moderate Trust | AE29: =IF(F29=TRUE,"Yes","No") -> No | AF29: =IF(ISBLANK(N29),"Unknown",N29) -> Low | AG29: =IF(O29=TRUE,"Yes","No") -> Yes | AH29: =IF(ISBLANK(S29),"Unknown",S29) -> Checked Official Source | AJ29: =IF(Q29>=8,"High Trust", IF(Q30>=5,"Moderate Trust","Low Trust")) -> High Trust | AL29: =ROUND(U29,1) -> 67.8 | AM29: =TRIM(J29) -> Masters
A30: Gemini | B30: technical_coding | C30: 75.1 | D30: 107 | E30: FALSE | F30: FALSE | G30: TRUE | H30: Moderate | I30: 65+ | J30: PhD | K30: Expert | L30: Beginner | M30: High | O30: TRUE | P30: TRUE | Q30: 9.5 | R30: TRUE | S30: Consulted Documentation | T30: 37.6 | U30: 69.68 | V30: FALSE | W30: Moderate Trust | AE30: =IF(F30=TRUE,"Yes","No") -> No | AF30: =IF(ISBLANK(N30),"Unknown",N30) -> Unknown | AG30: =IF(O30=TRUE,"Yes","No") -> Yes | AH30: =IF(ISBLANK(S30),"Unknown",S30) -> Consulted Documentation | AJ30: =IF(Q30>=8,"High Trust", IF(Q31>=5,"Moderate Trust","Low Trust")) -> High Trust | AL30: =ROUND(U30,1) -> 69.7 | AM30: =TRIM(J30) -> PhD
A31: ChatGPT-3.5 | B31: opinion_based | C31: 43.22 | D31: 345 | E31: TRUE | F31: TRUE | G31: TRUE | H31: Moderate | I31: 35-44 | J31: High School | K31: Low | L31: Intermediate | M31: High | N31: Medium | O31: FALSE | P31: FALSE | Q31: 4.3 | R31: FALSE | T31: 0 | U31: 26.69 | V31: TRUE | W31: Skeptical | AE31: =IF(F31=TRUE,"Yes","No") -> Yes | AF31: =IF(ISBLANK(N31),"Unknown",N31) -> Medium | AG31: =IF(O31=TRUE,"Yes","No") -> No | AH31: =IF(ISBLANK(S31),"Unknown",S31) -> Unknown | AJ31: =IF(Q31>=8,"High Trust", IF(Q32>=5,"Moderate Trust","Low Trust")) -> Moderate Trust | AL31: =ROUND(U31,1) -> 26.7 | AM31: =TRIM(J31) -> High School
A32: Gemini | B32: legal_advice | C32: 58.29 | D32: 776 | E32: TRUE | F32: FALSE | G32: TRUE | H32: Vague | I32: 65+ | J32: PhD | K32: Low | L32: First Time | M32: Low | N32: High | O32: TRUE | P32: TRUE | Q32: 10 | R32: FALSE | T32: 0 | U32: 63.76 | V32: FALSE | W32: Blind Trust | AE32: =IF(F32=TRUE,"Yes","No") -> No | AF32: =IF(ISBLANK(N32),"Unknown",N32) -> High | AG32: =IF(O32=TRUE,"Yes","No") -> Yes | AH32: =IF(ISBLANK(S32),"Unknown",S32) -> Unknown | AJ32: =IF(Q32>=8,"High Trust", IF(Q33>=5,"Moderate Trust","Low Trust")) -> High Trust | AL32: =ROUND(U32,1) -> 63.8 | AM32: =TRIM(J32) -> PhD
A33: Llama | B33: current_events | C33: 76.42 | D33: 466 | E33: TRUE | F33: FALSE | G33: FALSE | H33: Moderate | I33: 35-44 | J33: Masters | K33: Expert | L33: Expert | M33: Critical | O33: TRUE | P33: TRUE | Q33: 9.4 | R33: TRUE | S33: Google Search | T33: 30.9 | U33: 66.39 | V33: FALSE | W33: Moderate Trust | AE33: =IF(F33=TRUE,"Yes","No") -> No | AF33: =IF(ISBLANK(N33),"Unknown",N33) -> Unknown | AG33: =IF(O33=TRUE,"Yes","No") -> Yes | AH33: =IF(ISBLANK(S33),"Unknown",S33) -> Google Search | AJ33: =IF(Q33>=8,"High Trust", IF(Q34>=5,"Moderate Trust","Low Trust")) -> High Trust | AL33: =ROUND(U33,1) -> 66.4 | AM33: =TRIM(J33) -> Masters
A34: Gemini | B34: financial_advice | C34: 48.76 | D34: 60 | E34: FALSE | F34: TRUE | G34: TRUE | H34: Moderate | I34: 65+ | J34: Bachelors | K34: Medium | L34: Beginner | M34: Medium | N34: Low | O34: TRUE | P34: FALSE | Q34: 7.3 | R34: TRUE | S34: Checked Official Source | T34: 26.3 | U34: 47.61 | V34: FALSE | W34: Skeptical | AE34: =IF(F34=TRUE,"Yes","No") -> Yes | AF34: =IF(ISBLANK(N34),"Unknown",N34) -> Low | AG34: =IF(O34=TRUE,"Yes","No") -> Yes | AH34: =IF(ISBLANK(S34),"Unknown",S34) -> Checked Official Source | AJ34: =IF(Q34>=8,"High Trust", IF(Q35>=5,"Moderate Trust","Low Trust")) -> Moderate Trust | AL34: =ROUND(U34,1) -> 47.6 | AM34: =TRIM(J34) -> Bachelors
A35: GPT-4 | B35: math_calculation | C35: 92.82 | D35: 541 | E35: TRUE | F35: FALSE | G35: FALSE | H35: Moderate | I35: 65+ | J35: High School | K35: Medium | L35: Beginner | M35: Medium | P35: FALSE | Q35: 10 | R35: FALSE | T35: 0 | U35: 90.77 | V35: TRUE | W35: Blind Trust | AE35: =IF(F35=TRUE,"Yes","No") -> No | AF35: =IF(ISBLANK(N35),"Unknown",N35) -> Unknown | AG35: =IF(O35=TRUE,"Yes","No") -> No | AH35: =IF(ISBLANK(S35),"Unknown",S35) -> Unknown | AJ35: =IF(Q35>=8,"High Trust", IF(Q36>=5,"Moderate Trust","Low Trust")) -> High Trust | AL35: =ROUND(U35,1) -> 90.8 | AM35: =TRIM(J35) -> High School
A36: Mistral | B36: financial_advice | C36: 46.95 | D36: 521 | E36: FALSE | F36: FALSE | G36: FALSE | H36: Vague | I36: 55-64 | J36: High School | K36: Expert | L36: Intermediate | M36: Low | P36: FALSE | Q36: 5.2 | R36: TRUE | S36: Academic Paper | T36: 25.5 | U36: 58.55 | V36: TRUE | W36: Skeptical | AE36: =IF(F36=TRUE,"Yes","No") -> No | AF36: =IF(ISBLANK(N36),"Unknown",N36) -> Unknown | AG36: =IF(O36=TRUE,"Yes","No") -> No | AH36: =IF(ISBLANK(S36),"Unknown",S36) -> Academic Paper | AJ36: =IF(Q36>=8,"High Trust", IF(Q37>=5,"Moderate Trust","Low Trust")) -> Moderate Trust | AL36: =ROUND(U36,1) -> 58.6 | AM36: =TRIM(J36) -> High School
A37: Claude | B37: creative_writing | C37: 60.77 | D37: 442 | E37: TRUE | F37: TRUE | G37: TRUE | H37: Moderate | I37: 35-44 | J37: High School | K37: Expert | L37: Beginner | M37: Low | N37: Low | P37: FALSE | Q37: 8 | R37: TRUE | S37: Personal Testing | T37: 35 | U37: 71.84 | V37: TRUE | W37: Moderate Trust | AE37: =IF(F37=TRUE,"Yes","No") -> Yes | AF37: =IF(ISBLANK(N37),"Unknown",N37) -> Low | AG37: =IF(O37=TRUE,"Yes","No") -> No | AH37: =IF(ISBLANK(S37),"Unknown",S37) -> Personal Testing | AJ37: =IF(Q37>=8,"High Trust", IF(Q38>=5,"Moderate Trust","Low Trust")) -> High Trust | AL37: =ROUND(U37,1) -> 71.8 | AM37: =TRIM(J37) -> High School
A38: Claude | B38: financial_advice | C38: 56.58 | D38: 688 | E38: FALSE | F38: TRUE | G38: FALSE | H38: Moderate | I38: 35-44 | J38: High School | K38: Expert | L38: First Time | M38: Medium | P38: TRUE | Q38: 5.7 | R38: TRUE | S38: Google Search | T38: 14.8 | U38: 48.42 | V38: TRUE | W38: Skeptical | AE38: =IF(F38=TRUE,"Yes","No") -> Yes | AF38: =IF(ISBLANK(N38),"Unknown",N38) -> Unknown | AG38: =IF(O38=TRUE,"Yes","No") -> No | AH38: =IF(ISBLANK(S38),"Unknown",S38) -> Google Search | AJ38: =IF(Q38>=8,"High Trust", IF(Q39>=5,"Moderate Trust","Low Trust")) -> Moderate Trust | AL38: =ROUND(U38,1) -> 48.4 | AM38: =TRIM(J38) -> High School
A39: Claude | B39: math_calculation | C39: 98.66 | D39: 109 | E39: FALSE | F39: TRUE | G39: TRUE | H39: Specific | I39: 45-54 | J39: Professional | K39: High | L39: Beginner | M39: Medium | O39: FALSE | P39: TRUE | Q39: 9.1 | R39: TRUE | S39: Cross-referenced Multiple AIs | T39: 16.6 | U39: 89.95 | V39: TRUE | W39: Moderate Trust | AE39: =IF(F39=TRUE,"Yes","No") -> Yes | AF39: =IF(ISBLANK(N39),"Unknown",N39) -> Unknown | AG39: =IF(O39=TRUE,"Yes","No") -> No | AH39: =IF(ISBLANK(S39),"Unknown",S39) -> Cross-referenced Multiple AIs | AJ39: =IF(Q39>=8,"High Trust", IF(Q40>=5,"Moderate Trust","Low Trust")) -> High Trust | AL39: =ROUND(U39,1) -> 90 | AM39: =TRIM(J39) -> Professional
A40: Claude | B40: math_calculation | C40: 89.07 | D40: 258 | E40: FALSE | F40: FALSE | G40: TRUE | H40: Very Specific | I40: 55-64 | J40: Masters | K40: Expert | L40: Expert | M40: High | N40: Medium | O40: TRUE | P40: FALSE | Q40: 10 | R40: TRUE | S40: Asked Colleague | T40: 37.6 | U40: 89.53 | V40: TRUE | W40: Moderate Trust | AE40: =IF(F40=TRUE,"Yes","No") -> No | AF40: =IF(ISBLANK(N40),"Unknown",N40) -> Medium | AG40: =IF(O40=TRUE,"Yes","No") -> Yes | AH40: =IF(ISBLANK(S40),"Unknown",S40) -> Asked Colleague | AJ40: =IF(Q40>=8,"High Trust", IF(Q41>=5,"Moderate Trust","Low Trust")) -> High Trust | AL40: =ROUND(U40,1) -> 89.5 | AM40: =TRIM(J40) -> Masters
...

Sheet Calculations
A1: Metric | B1: Formula (Editable in Excel) | F1: Average Trust for Claude
A2: Total Records | B2: =COUNTA(Clean_Data!A:A)-1 -> 1000 | F2: =AVERAGEIF(Clean_Data!A2,"Claude",Clean_Data!Q2) -> 10
A3: Average Trust Score | B3: =AVERAGE(Clean_Data!Q:Q) -> 7.905
A4: Average Accuracy | B4: =AVERAGE(Clean_Data!U:U) -> 69.98202
A5: Fact Check Yes - Avg Trust | B5: =AVERAGEIF(Clean_Data!R:R,TRUE,Clean_Data!Q:Q) -> 7.5257962
A6: Fact Check No - Avg Trust | B6: =AVERAGEIF(Clean_Data!R:R,FALSE,Clean_Data!Q:Q) -> 8.5451613

Sheet Lookups
A1: Education Level | B1: Weight Score | D1: VLOOKUPS | G1: LOOKUPS
A2: High School | B2: 1 | E2: =VLOOKUP(A2, Lookups!$A$2:$B$5,2,FALSE) -> 1 | H2: =LOOKUP(A2, A2:A5, B2:B5) -> 2
A3: Bachelors | B3: 2 | E3: =VLOOKUP(A3, Lookups!$A$2:$B$5,2,FALSE) -> 2
A4: Masters | B4: 3 | E4: =VLOOKUP(A4, Lookups!$A$2:$B$5,2,FALSE) -> 3
A5: PhD | B5: 4 | E5: =VLOOKUP(A5, Lookups!$A$2:$B$5,2,FALSE) -> 4 | G5: INDEX
H6: =INDEX(Lookups!B2:B5,3) -> 3
G8: INDEX + MATCH
H9: =IFERROR( INDEX(Lookups!B2:B5, MATCH(E2,Lookups!A2:A5,0)), "Not Found") -> Not Found
A11: Education Level | B11: High School | C11: Bachelors | D11: Masters | E11: PhD
A12: Weight Score | B12: 1 | C12: 2 | D12: 3 | E12: 4
A14: HLOOKUPS | B14: =HLOOKUP(D11, B11:E12, 2, FALSE) -> 3

Sheet Pivot_Table
A1: AI Model | B1: Avg Trust Score | C1: Avg Accuracy %
A2: ChatGPT-3.5 | B2: =AVERAGEIF(Clean_Data!$A:$A,A2,Clean_Data!$Q:$Q) -> 7.655 | C2: =AVERAGEIF(Clean_Data!$A:$A,A2,Clean_Data!$U:$U) -> 69.400063
A3: Claude | B3: =AVERAGEIF(Clean_Data!$A:$A,A3,Clean_Data!$Q:$Q) -> 8.1467836 | C3: =AVERAGEIF(Clean_Data!$A:$A,A3,Clean_Data!$U:$U) -> 70.712865
A4: GPT-4 | B4: =AVERAGEIF(Clean_Data!$A:$A,A4,Clean_Data!$Q:$Q) -> 8.1358974 | C4: =AVERAGEIF(Clean_Data!$A:$A,A4,Clean_Data!$U:$U) -> 71.203718
A5: Gemini | B5: =AVERAGEIF(Clean_Data!$A:$A,A5,Clean_Data!$Q:$Q) -> 7.7915789 | C5: =AVERAGEIF(Clean_Data!$A:$A,A5,Clean_Data!$U:$U) -> 69.306263
A6: Llama | B6: =AVERAGEIF(Clean_Data!$A:$A,A6,Clean_Data!$Q:$Q) -> 7.7715152 | C6: =AVERAGEIF(Clean_Data!$A:$A,A6,Clean_Data!$U:$U) -> 68.508121
A7: Mistral | B7: =AVERAGEIF(Clean_Data!$A:$A,A7,Clean_Data!$Q:$Q) -> 7.9443038 | C7: =AVERAGEIF(Clean_Data!$A:$A,A7,Clean_Data!$U:$U) -> 70.925949

Sheet Analysis
A1: Performed Fact Check | B1: Avg Trust Score
A2: FALSE | B2: =AVERAGEIF(Clean_Data!R:R,FALSE,Clean_Data!Q:Q) -> 8.5451613
A3: TRUE | B3: 7.5257962
A11: Education Level | B11: Avg Trust Score
A12: Bachelors | B12: =AVERAGEIF(Clean_Data!AM:AM,A12,Clean_Data!Q:Q) -> 8.0492308
A13: High School | B13: =AVERAGEIF(Clean_Data!AM:AM,A13,Clean_Data!Q:Q) -> 7.8938776
A14: Masters | B14: =AVERAGEIF(Clean_Data!AM:AM,A14,Clean_Data!Q:Q) -> 7.8153465
A15: PhD | B15: =AVERAGEIF(Clean_Data!AM:AM,A15,Clean_Data!Q:Q) -> 7.8912844
A16: Professional | B16: =AVERAGEIF(Clean_Data!AM:AM,A16,Clean_Data!Q:Q) -> 7.8793651

Sheet Data Model
B3: Row Labels | C3: Avg Trust | D3: Avg Accuracy
B4: ChatGPT-3.5 | C4: 7.655 | D4: 69.400063
B5: Claude | C5: 8.1467836 | D5: 70.712865
B6: Gemini | C6: 7.7915789 | D6: 69.306263
B7: GPT-4 | C7: 8.1358974 | D7: 71.203718
B8: Llama | C8: 7.7715152 | D8: 68.508121
B9: Mistral | C9: 7.9443038 | D9: 70.925949 | H9: Row Labels | I9: Avg Trust
B10: Grand Total | C10: 7.905 | D10: 69.98202 | H10: High School | I10: 7.8938776
H11: Bachelors | I11: 8.0492308
H12: Masters | I12: 7.8153465
H13: PhD | I13: 7.8912844
H14: Professional | I14: 7.8793651
H15: Grand Total | I15: 7.905
B16: Row Labels | C16: Avg Trust
B17: FALSE | C17: 8.5451613
B18: TRUE | C18: 7.5257962
B19: Grand Total | C19: 7.905
K22: `

Sheet Dashboard
